[2021-09-13 17:54:44] [INFO] red: Begin updating guild configs to support multiple mod/admin roles
[2021-09-13 17:54:44] [INFO] red: Done updating guild configs to support multiple mod/admin roles
[2021-09-13 17:54:44] [INFO] red: Moving shared API tokens to a custom group
[2021-09-13 17:54:47] [INFO] red: Connected to Discord. Getting ready...
[2021-09-13 18:00:42] [INFO] red.main: Shutting down with exit code: ExitCodes.SHUTDOWN
[2021-09-13 18:00:42] [INFO] red.main: Please wait, cleaning up a bit more
[2021-09-13 18:01:07] [INFO] red: Connected to Discord. Getting ready...
[2021-09-13 18:11:07] [ERROR] discord.shard: Attempting a reconnect for shard ID 0 in 0.43s
Traceback (most recent call last):
  File "C:\Users\sugan\redenv\lib\site-packages\aiohttp\connector.py", line 999, in _create_direct_connection
    hosts = await asyncio.shield(host_resolved)
  File "C:\Users\sugan\redenv\lib\site-packages\aiohttp\connector.py", line 865, in _resolve_host
    addrs = await self._resolver.resolve(host, port, family=self._family)
  File "C:\Users\sugan\redenv\lib\site-packages\aiohttp\resolver.py", line 31, in resolve
    infos = await self._loop.getaddrinfo(
  File "C:\Users\sugan\AppData\Local\Programs\Python\Python39\lib\asyncio\base_events.py", line 856, in getaddrinfo
    return await self.run_in_executor(
  File "C:\Users\sugan\AppData\Local\Programs\Python\Python39\lib\concurrent\futures\thread.py", line 52, in run
    result = self.fn(*self.args, **self.kwargs)
  File "C:\Users\sugan\AppData\Local\Programs\Python\Python39\lib\socket.py", line 954, in getaddrinfo
    for res in _socket.getaddrinfo(host, port, family, type, proto, flags):
socket.gaierror: [Errno 11001] getaddrinfo failed

The above exception was the direct cause of the following exception:

Traceback (most recent call last):
  File "C:\Users\sugan\redenv\lib\site-packages\discord\shard.py", line 173, in reidentify
    self.ws = await asyncio.wait_for(coro, timeout=60.0)
  File "C:\Users\sugan\AppData\Local\Programs\Python\Python39\lib\asyncio\tasks.py", line 481, in wait_for
    return fut.result()
  File "C:\Users\sugan\redenv\lib\site-packages\discord\gateway.py", line 305, in from_client
    gateway = gateway or await client.http.get_gateway()
  File "C:\Users\sugan\redenv\lib\site-packages\discord\http.py", line 967, in get_gateway
    data = await self.request(Route('GET', '/gateway'))
  File "C:\Users\sugan\redenv\lib\site-packages\discord\http.py", line 192, in request
    async with self.__session.request(method, url, **kwargs) as r:
  File "C:\Users\sugan\redenv\lib\site-packages\aiohttp\client.py", line 1117, in __aenter__
    self._resp = await self._coro
  File "C:\Users\sugan\redenv\lib\site-packages\aiohttp\client.py", line 520, in _request
    conn = await self._connector.connect(
  File "C:\Users\sugan\redenv\lib\site-packages\aiohttp\connector.py", line 535, in connect
    proto = await self._create_connection(req, traces, timeout)
  File "C:\Users\sugan\redenv\lib\site-packages\aiohttp\connector.py", line 892, in _create_connection
    _, proto = await self._create_direct_connection(req, traces, timeout)
  File "C:\Users\sugan\redenv\lib\site-packages\aiohttp\connector.py", line 1011, in _create_direct_connection
    raise ClientConnectorError(req.connection_key, exc) from exc
aiohttp.client_exceptions.ClientConnectorError: Cannot connect to host discord.com:443 ssl:default [getaddrinfo failed]
[2021-09-13 18:11:09] [ERROR] discord.shard: Attempting a reconnect for shard ID 0 in 1.19s
Traceback (most recent call last):
  File "C:\Users\sugan\redenv\lib\site-packages\aiohttp\connector.py", line 999, in _create_direct_connection
    hosts = await asyncio.shield(host_resolved)
  File "C:\Users\sugan\redenv\lib\site-packages\aiohttp\connector.py", line 865, in _resolve_host
    addrs = await self._resolver.resolve(host, port, family=self._family)
  File "C:\Users\sugan\redenv\lib\site-packages\aiohttp\resolver.py", line 31, in resolve
    infos = await self._loop.getaddrinfo(
  File "C:\Users\sugan\AppData\Local\Programs\Python\Python39\lib\asyncio\base_events.py", line 856, in getaddrinfo
    return await self.run_in_executor(
  File "C:\Users\sugan\AppData\Local\Programs\Python\Python39\lib\concurrent\futures\thread.py", line 52, in run
    result = self.fn(*self.args, **self.kwargs)
  File "C:\Users\sugan\AppData\Local\Programs\Python\Python39\lib\socket.py", line 954, in getaddrinfo
    for res in _socket.getaddrinfo(host, port, family, type, proto, flags):
socket.gaierror: [Errno 11001] getaddrinfo failed

The above exception was the direct cause of the following exception:

Traceback (most recent call last):
  File "C:\Users\sugan\redenv\lib\site-packages\discord\shard.py", line 187, in reconnect
    self.ws = await asyncio.wait_for(coro, timeout=60.0)
  File "C:\Users\sugan\AppData\Local\Programs\Python\Python39\lib\asyncio\tasks.py", line 481, in wait_for
    return fut.result()
  File "C:\Users\sugan\redenv\lib\site-packages\discord\gateway.py", line 305, in from_client
    gateway = gateway or await client.http.get_gateway()
  File "C:\Users\sugan\redenv\lib\site-packages\discord\http.py", line 967, in get_gateway
    data = await self.request(Route('GET', '/gateway'))
  File "C:\Users\sugan\redenv\lib\site-packages\discord\http.py", line 192, in request
    async with self.__session.request(method, url, **kwargs) as r:
  File "C:\Users\sugan\redenv\lib\site-packages\aiohttp\client.py", line 1117, in __aenter__
    self._resp = await self._coro
  File "C:\Users\sugan\redenv\lib\site-packages\aiohttp\client.py", line 520, in _request
    conn = await self._connector.connect(
  File "C:\Users\sugan\redenv\lib\site-packages\aiohttp\connector.py", line 535, in connect
    proto = await self._create_connection(req, traces, timeout)
  File "C:\Users\sugan\redenv\lib\site-packages\aiohttp\connector.py", line 892, in _create_connection
    _, proto = await self._create_direct_connection(req, traces, timeout)
  File "C:\Users\sugan\redenv\lib\site-packages\aiohttp\connector.py", line 1011, in _create_direct_connection
    raise ClientConnectorError(req.connection_key, exc) from exc
aiohttp.client_exceptions.ClientConnectorError: Cannot connect to host discord.com:443 ssl:default [getaddrinfo failed]
[2021-09-13 18:11:12] [ERROR] discord.shard: Attempting a reconnect for shard ID 0 in 4.99s
Traceback (most recent call last):
  File "C:\Users\sugan\redenv\lib\site-packages\aiohttp\connector.py", line 999, in _create_direct_connection
    hosts = await asyncio.shield(host_resolved)
  File "C:\Users\sugan\redenv\lib\site-packages\aiohttp\connector.py", line 865, in _resolve_host
    addrs = await self._resolver.resolve(host, port, family=self._family)
  File "C:\Users\sugan\redenv\lib\site-packages\aiohttp\resolver.py", line 31, in resolve
    infos = await self._loop.getaddrinfo(
  File "C:\Users\sugan\AppData\Local\Programs\Python\Python39\lib\asyncio\base_events.py", line 856, in getaddrinfo
    return await self.run_in_executor(
  File "C:\Users\sugan\AppData\Local\Programs\Python\Python39\lib\concurrent\futures\thread.py", line 52, in run
    result = self.fn(*self.args, **self.kwargs)
  File "C:\Users\sugan\AppData\Local\Programs\Python\Python39\lib\socket.py", line 954, in getaddrinfo
    for res in _socket.getaddrinfo(host, port, family, type, proto, flags):
socket.gaierror: [Errno 11001] getaddrinfo failed

The above exception was the direct cause of the following exception:

Traceback (most recent call last):
  File "C:\Users\sugan\redenv\lib\site-packages\discord\shard.py", line 187, in reconnect
    self.ws = await asyncio.wait_for(coro, timeout=60.0)
  File "C:\Users\sugan\AppData\Local\Programs\Python\Python39\lib\asyncio\tasks.py", line 481, in wait_for
    return fut.result()
  File "C:\Users\sugan\redenv\lib\site-packages\discord\gateway.py", line 305, in from_client
    gateway = gateway or await client.http.get_gateway()
  File "C:\Users\sugan\redenv\lib\site-packages\discord\http.py", line 967, in get_gateway
    data = await self.request(Route('GET', '/gateway'))
  File "C:\Users\sugan\redenv\lib\site-packages\discord\http.py", line 192, in request
    async with self.__session.request(method, url, **kwargs) as r:
  File "C:\Users\sugan\redenv\lib\site-packages\aiohttp\client.py", line 1117, in __aenter__
    self._resp = await self._coro
  File "C:\Users\sugan\redenv\lib\site-packages\aiohttp\client.py", line 520, in _request
    conn = await self._connector.connect(
  File "C:\Users\sugan\redenv\lib\site-packages\aiohttp\connector.py", line 535, in connect
    proto = await self._create_connection(req, traces, timeout)
  File "C:\Users\sugan\redenv\lib\site-packages\aiohttp\connector.py", line 892, in _create_connection
    _, proto = await self._create_direct_connection(req, traces, timeout)
  File "C:\Users\sugan\redenv\lib\site-packages\aiohttp\connector.py", line 1011, in _create_direct_connection
    raise ClientConnectorError(req.connection_key, exc) from exc
aiohttp.client_exceptions.ClientConnectorError: Cannot connect to host discord.com:443 ssl:default [getaddrinfo failed]
[2021-09-13 18:11:18] [ERROR] discord.shard: Attempting a reconnect for shard ID 0 in 13.73s
Traceback (most recent call last):
  File "C:\Users\sugan\redenv\lib\site-packages\aiohttp\connector.py", line 999, in _create_direct_connection
    hosts = await asyncio.shield(host_resolved)
  File "C:\Users\sugan\redenv\lib\site-packages\aiohttp\connector.py", line 865, in _resolve_host
    addrs = await self._resolver.resolve(host, port, family=self._family)
  File "C:\Users\sugan\redenv\lib\site-packages\aiohttp\resolver.py", line 31, in resolve
    infos = await self._loop.getaddrinfo(
  File "C:\Users\sugan\AppData\Local\Programs\Python\Python39\lib\asyncio\base_events.py", line 856, in getaddrinfo
    return await self.run_in_executor(
  File "C:\Users\sugan\AppData\Local\Programs\Python\Python39\lib\concurrent\futures\thread.py", line 52, in run
    result = self.fn(*self.args, **self.kwargs)
  File "C:\Users\sugan\AppData\Local\Programs\Python\Python39\lib\socket.py", line 954, in getaddrinfo
    for res in _socket.getaddrinfo(host, port, family, type, proto, flags):
socket.gaierror: [Errno 11001] getaddrinfo failed

The above exception was the direct cause of the following exception:

Traceback (most recent call last):
  File "C:\Users\sugan\redenv\lib\site-packages\discord\shard.py", line 187, in reconnect
    self.ws = await asyncio.wait_for(coro, timeout=60.0)
  File "C:\Users\sugan\AppData\Local\Programs\Python\Python39\lib\asyncio\tasks.py", line 481, in wait_for
    return fut.result()
  File "C:\Users\sugan\redenv\lib\site-packages\discord\gateway.py", line 305, in from_client
    gateway = gateway or await client.http.get_gateway()
  File "C:\Users\sugan\redenv\lib\site-packages\discord\http.py", line 967, in get_gateway
    data = await self.request(Route('GET', '/gateway'))
  File "C:\Users\sugan\redenv\lib\site-packages\discord\http.py", line 192, in request
    async with self.__session.request(method, url, **kwargs) as r:
  File "C:\Users\sugan\redenv\lib\site-packages\aiohttp\client.py", line 1117, in __aenter__
    self._resp = await self._coro
  File "C:\Users\sugan\redenv\lib\site-packages\aiohttp\client.py", line 520, in _request
    conn = await self._connector.connect(
  File "C:\Users\sugan\redenv\lib\site-packages\aiohttp\connector.py", line 535, in connect
    proto = await self._create_connection(req, traces, timeout)
  File "C:\Users\sugan\redenv\lib\site-packages\aiohttp\connector.py", line 892, in _create_connection
    _, proto = await self._create_direct_connection(req, traces, timeout)
  File "C:\Users\sugan\redenv\lib\site-packages\aiohttp\connector.py", line 1011, in _create_direct_connection
    raise ClientConnectorError(req.connection_key, exc) from exc
aiohttp.client_exceptions.ClientConnectorError: Cannot connect to host discord.com:443 ssl:default [getaddrinfo failed]
[2021-09-13 18:11:33] [ERROR] discord.shard: Attempting a reconnect for shard ID 0 in 2.15s
Traceback (most recent call last):
  File "C:\Users\sugan\redenv\lib\site-packages\aiohttp\connector.py", line 999, in _create_direct_connection
    hosts = await asyncio.shield(host_resolved)
  File "C:\Users\sugan\redenv\lib\site-packages\aiohttp\connector.py", line 865, in _resolve_host
    addrs = await self._resolver.resolve(host, port, family=self._family)
  File "C:\Users\sugan\redenv\lib\site-packages\aiohttp\resolver.py", line 31, in resolve
    infos = await self._loop.getaddrinfo(
  File "C:\Users\sugan\AppData\Local\Programs\Python\Python39\lib\asyncio\base_events.py", line 856, in getaddrinfo
    return await self.run_in_executor(
  File "C:\Users\sugan\AppData\Local\Programs\Python\Python39\lib\concurrent\futures\thread.py", line 52, in run
    result = self.fn(*self.args, **self.kwargs)
  File "C:\Users\sugan\AppData\Local\Programs\Python\Python39\lib\socket.py", line 954, in getaddrinfo
    for res in _socket.getaddrinfo(host, port, family, type, proto, flags):
socket.gaierror: [Errno 11001] getaddrinfo failed

The above exception was the direct cause of the following exception:

Traceback (most recent call last):
  File "C:\Users\sugan\redenv\lib\site-packages\discord\shard.py", line 187, in reconnect
    self.ws = await asyncio.wait_for(coro, timeout=60.0)
  File "C:\Users\sugan\AppData\Local\Programs\Python\Python39\lib\asyncio\tasks.py", line 481, in wait_for
    return fut.result()
  File "C:\Users\sugan\redenv\lib\site-packages\discord\gateway.py", line 305, in from_client
    gateway = gateway or await client.http.get_gateway()
  File "C:\Users\sugan\redenv\lib\site-packages\discord\http.py", line 967, in get_gateway
    data = await self.request(Route('GET', '/gateway'))
  File "C:\Users\sugan\redenv\lib\site-packages\discord\http.py", line 192, in request
    async with self.__session.request(method, url, **kwargs) as r:
  File "C:\Users\sugan\redenv\lib\site-packages\aiohttp\client.py", line 1117, in __aenter__
    self._resp = await self._coro
  File "C:\Users\sugan\redenv\lib\site-packages\aiohttp\client.py", line 520, in _request
    conn = await self._connector.connect(
  File "C:\Users\sugan\redenv\lib\site-packages\aiohttp\connector.py", line 535, in connect
    proto = await self._create_connection(req, traces, timeout)
  File "C:\Users\sugan\redenv\lib\site-packages\aiohttp\connector.py", line 892, in _create_connection
    _, proto = await self._create_direct_connection(req, traces, timeout)
  File "C:\Users\sugan\redenv\lib\site-packages\aiohttp\connector.py", line 1011, in _create_direct_connection
    raise ClientConnectorError(req.connection_key, exc) from exc
aiohttp.client_exceptions.ClientConnectorError: Cannot connect to host discord.com:443 ssl:default [getaddrinfo failed]
[2021-09-13 18:11:36] [ERROR] discord.shard: Attempting a reconnect for shard ID 0 in 11.77s
Traceback (most recent call last):
  File "C:\Users\sugan\redenv\lib\site-packages\aiohttp\connector.py", line 999, in _create_direct_connection
    hosts = await asyncio.shield(host_resolved)
  File "C:\Users\sugan\redenv\lib\site-packages\aiohttp\connector.py", line 865, in _resolve_host
    addrs = await self._resolver.resolve(host, port, family=self._family)
  File "C:\Users\sugan\redenv\lib\site-packages\aiohttp\resolver.py", line 31, in resolve
    infos = await self._loop.getaddrinfo(
  File "C:\Users\sugan\AppData\Local\Programs\Python\Python39\lib\asyncio\base_events.py", line 856, in getaddrinfo
    return await self.run_in_executor(
  File "C:\Users\sugan\AppData\Local\Programs\Python\Python39\lib\concurrent\futures\thread.py", line 52, in run
    result = self.fn(*self.args, **self.kwargs)
  File "C:\Users\sugan\AppData\Local\Programs\Python\Python39\lib\socket.py", line 954, in getaddrinfo
    for res in _socket.getaddrinfo(host, port, family, type, proto, flags):
socket.gaierror: [Errno 11001] getaddrinfo failed

The above exception was the direct cause of the following exception:

Traceback (most recent call last):
  File "C:\Users\sugan\redenv\lib\site-packages\discord\shard.py", line 187, in reconnect
    self.ws = await asyncio.wait_for(coro, timeout=60.0)
  File "C:\Users\sugan\AppData\Local\Programs\Python\Python39\lib\asyncio\tasks.py", line 481, in wait_for
    return fut.result()
  File "C:\Users\sugan\redenv\lib\site-packages\discord\gateway.py", line 305, in from_client
    gateway = gateway or await client.http.get_gateway()
  File "C:\Users\sugan\redenv\lib\site-packages\discord\http.py", line 967, in get_gateway
    data = await self.request(Route('GET', '/gateway'))
  File "C:\Users\sugan\redenv\lib\site-packages\discord\http.py", line 192, in request
    async with self.__session.request(method, url, **kwargs) as r:
  File "C:\Users\sugan\redenv\lib\site-packages\aiohttp\client.py", line 1117, in __aenter__
    self._resp = await self._coro
  File "C:\Users\sugan\redenv\lib\site-packages\aiohttp\client.py", line 520, in _request
    conn = await self._connector.connect(
  File "C:\Users\sugan\redenv\lib\site-packages\aiohttp\connector.py", line 535, in connect
    proto = await self._create_connection(req, traces, timeout)
  File "C:\Users\sugan\redenv\lib\site-packages\aiohttp\connector.py", line 892, in _create_connection
    _, proto = await self._create_direct_connection(req, traces, timeout)
  File "C:\Users\sugan\redenv\lib\site-packages\aiohttp\connector.py", line 1011, in _create_direct_connection
    raise ClientConnectorError(req.connection_key, exc) from exc
aiohttp.client_exceptions.ClientConnectorError: Cannot connect to host discord.com:443 ssl:default [getaddrinfo failed]
[2021-09-13 18:11:49] [ERROR] discord.shard: Attempting a reconnect for shard ID 0 in 116.13s
Traceback (most recent call last):
  File "C:\Users\sugan\redenv\lib\site-packages\aiohttp\connector.py", line 999, in _create_direct_connection
    hosts = await asyncio.shield(host_resolved)
  File "C:\Users\sugan\redenv\lib\site-packages\aiohttp\connector.py", line 865, in _resolve_host
    addrs = await self._resolver.resolve(host, port, family=self._family)
  File "C:\Users\sugan\redenv\lib\site-packages\aiohttp\resolver.py", line 31, in resolve
    infos = await self._loop.getaddrinfo(
  File "C:\Users\sugan\AppData\Local\Programs\Python\Python39\lib\asyncio\base_events.py", line 856, in getaddrinfo
    return await self.run_in_executor(
  File "C:\Users\sugan\AppData\Local\Programs\Python\Python39\lib\concurrent\futures\thread.py", line 52, in run
    result = self.fn(*self.args, **self.kwargs)
  File "C:\Users\sugan\AppData\Local\Programs\Python\Python39\lib\socket.py", line 954, in getaddrinfo
    for res in _socket.getaddrinfo(host, port, family, type, proto, flags):
socket.gaierror: [Errno 11001] getaddrinfo failed

The above exception was the direct cause of the following exception:

Traceback (most recent call last):
  File "C:\Users\sugan\redenv\lib\site-packages\discord\shard.py", line 187, in reconnect
    self.ws = await asyncio.wait_for(coro, timeout=60.0)
  File "C:\Users\sugan\AppData\Local\Programs\Python\Python39\lib\asyncio\tasks.py", line 481, in wait_for
    return fut.result()
  File "C:\Users\sugan\redenv\lib\site-packages\discord\gateway.py", line 305, in from_client
    gateway = gateway or await client.http.get_gateway()
  File "C:\Users\sugan\redenv\lib\site-packages\discord\http.py", line 967, in get_gateway
    data = await self.request(Route('GET', '/gateway'))
  File "C:\Users\sugan\redenv\lib\site-packages\discord\http.py", line 192, in request
    async with self.__session.request(method, url, **kwargs) as r:
  File "C:\Users\sugan\redenv\lib\site-packages\aiohttp\client.py", line 1117, in __aenter__
    self._resp = await self._coro
  File "C:\Users\sugan\redenv\lib\site-packages\aiohttp\client.py", line 520, in _request
    conn = await self._connector.connect(
  File "C:\Users\sugan\redenv\lib\site-packages\aiohttp\connector.py", line 535, in connect
    proto = await self._create_connection(req, traces, timeout)
  File "C:\Users\sugan\redenv\lib\site-packages\aiohttp\connector.py", line 892, in _create_connection
    _, proto = await self._create_direct_connection(req, traces, timeout)
  File "C:\Users\sugan\redenv\lib\site-packages\aiohttp\connector.py", line 1011, in _create_direct_connection
    raise ClientConnectorError(req.connection_key, exc) from exc
aiohttp.client_exceptions.ClientConnectorError: Cannot connect to host discord.com:443 ssl:default [getaddrinfo failed]
[2021-09-13 18:16:09] [INFO] red.main: Shutting down with exit code: ExitCodes.SHUTDOWN
[2021-09-13 18:16:09] [INFO] red.main: Please wait, cleaning up a bit more
[2021-09-13 18:16:28] [INFO] red: Connected to Discord. Getting ready...
[2021-09-13 18:34:41] [INFO] red.main: Shutting down with exit code: ExitCodes.SHUTDOWN
[2021-09-13 18:34:41] [INFO] red.main: Please wait, cleaning up a bit more
[2021-09-13 19:12:28] [INFO] red: Connected to Discord. Getting ready...
[2021-09-13 19:40:54] [ERROR] discord.shard: Attempting a reconnect for shard ID 0 in 0.83s
Traceback (most recent call last):
  File "C:\Users\sugan\redenv\lib\site-packages\aiohttp\connector.py", line 999, in _create_direct_connection
    hosts = await asyncio.shield(host_resolved)
  File "C:\Users\sugan\redenv\lib\site-packages\aiohttp\connector.py", line 865, in _resolve_host
    addrs = await self._resolver.resolve(host, port, family=self._family)
  File "C:\Users\sugan\redenv\lib\site-packages\aiohttp\resolver.py", line 31, in resolve
    infos = await self._loop.getaddrinfo(
  File "C:\Users\sugan\AppData\Local\Programs\Python\Python39\lib\asyncio\base_events.py", line 856, in getaddrinfo
    return await self.run_in_executor(
  File "C:\Users\sugan\AppData\Local\Programs\Python\Python39\lib\concurrent\futures\thread.py", line 52, in run
    result = self.fn(*self.args, **self.kwargs)
  File "C:\Users\sugan\AppData\Local\Programs\Python\Python39\lib\socket.py", line 954, in getaddrinfo
    for res in _socket.getaddrinfo(host, port, family, type, proto, flags):
socket.gaierror: [Errno 11001] getaddrinfo failed

The above exception was the direct cause of the following exception:

Traceback (most recent call last):
  File "C:\Users\sugan\redenv\lib\site-packages\discord\shard.py", line 173, in reidentify
    self.ws = await asyncio.wait_for(coro, timeout=60.0)
  File "C:\Users\sugan\AppData\Local\Programs\Python\Python39\lib\asyncio\tasks.py", line 481, in wait_for
    return fut.result()
  File "C:\Users\sugan\redenv\lib\site-packages\discord\gateway.py", line 305, in from_client
    gateway = gateway or await client.http.get_gateway()
  File "C:\Users\sugan\redenv\lib\site-packages\discord\http.py", line 967, in get_gateway
    data = await self.request(Route('GET', '/gateway'))
  File "C:\Users\sugan\redenv\lib\site-packages\discord\http.py", line 192, in request
    async with self.__session.request(method, url, **kwargs) as r:
  File "C:\Users\sugan\redenv\lib\site-packages\aiohttp\client.py", line 1117, in __aenter__
    self._resp = await self._coro
  File "C:\Users\sugan\redenv\lib\site-packages\aiohttp\client.py", line 520, in _request
    conn = await self._connector.connect(
  File "C:\Users\sugan\redenv\lib\site-packages\aiohttp\connector.py", line 535, in connect
    proto = await self._create_connection(req, traces, timeout)
  File "C:\Users\sugan\redenv\lib\site-packages\aiohttp\connector.py", line 892, in _create_connection
    _, proto = await self._create_direct_connection(req, traces, timeout)
  File "C:\Users\sugan\redenv\lib\site-packages\aiohttp\connector.py", line 1011, in _create_direct_connection
    raise ClientConnectorError(req.connection_key, exc) from exc
aiohttp.client_exceptions.ClientConnectorError: Cannot connect to host discord.com:443 ssl:default [getaddrinfo failed]
[2021-09-13 20:33:24] [INFO] red.main: Shutting down with exit code: ExitCodes.SHUTDOWN
[2021-09-13 20:33:24] [INFO] red.main: Please wait, cleaning up a bit more
[2021-09-13 20:34:05] [INFO] red: Connected to Discord. Getting ready...
[2021-09-13 21:11:59] [INFO] red.main: Shutting down with exit code: ExitCodes.SHUTDOWN
[2021-09-13 21:11:59] [INFO] red.main: Please wait, cleaning up a bit more
[2021-09-14 05:50:50] [INFO] red: Connected to Discord. Getting ready...
[2021-09-14 06:12:12] [INFO] red.cleanup: Sugan(778438128527867915) deleted 6 messages sent by the bot in channel bot-commands.
[2021-09-14 06:12:15] [WARNING] discord.http: We are being rate limited. Retrying in 2.63 seconds. Handled under the bucket "880624299701055539:None:/channels/{channel_id}/messages/{message_id}"
[2021-09-14 06:12:42] [INFO] red.cleanup: Sugan(778438128527867915) deleted 8 messages sent by the bot in channel bot-commands.
[2021-09-14 06:12:46] [WARNING] discord.http: We are being rate limited. Retrying in 1.94 seconds. Handled under the bucket "819856954095960105:None:/channels/{channel_id}/messages/{message_id}"
[2021-09-14 06:13:05] [INFO] red.cleanup: Sugan(778438128527867915) deleted 10 messages sent by the bot in channel bot-commands.
[2021-09-14 06:13:09] [WARNING] discord.http: We are being rate limited. Retrying in 1.81 seconds. Handled under the bucket "819856954095960105:None:/channels/{channel_id}/messages/{message_id}"
[2021-09-14 06:14:14] [INFO] red.cleanup: Sugan(778438128527867915) deleted 6 messages in channel #bot-commands.
[2021-09-14 06:14:48] [INFO] red.cleanup: Sugan(778438128527867915) deleted 1 messages sent by the bot in channel bot-commands.
[2021-09-14 06:39:10] [INFO] red.mod: Sugan(778438128527867915) banned Selvakumar(856083940011671573), deleting 1 days worth of messages.
[2021-09-14 06:45:19] [INFO] red.cleanup: Sugan(778438128527867915) deleted 2 messages sent by the bot in channel bot-commands.
[2021-09-14 06:58:36] [ERROR] red: Package loading failed
Traceback (most recent call last):
  File "C:\Users\sugan\redenv\lib\site-packages\redbot\core\core_commands.py", line 176, in _load
    await bot.load_extension(spec)
  File "C:\Users\sugan\redenv\lib\site-packages\redbot\core\bot.py", line 1510, in load_extension
    lib = spec.loader.load_module()
  File "<frozen importlib._bootstrap_external>", line 529, in _check_name_wrapper
  File "<frozen importlib._bootstrap_external>", line 1029, in load_module
  File "<frozen importlib._bootstrap_external>", line 854, in load_module
  File "<frozen importlib._bootstrap>", line 274, in _load_module_shim
  File "<frozen importlib._bootstrap>", line 711, in _load
  File "<frozen importlib._bootstrap>", line 680, in _load_unlocked
  File "<frozen importlib._bootstrap_external>", line 850, in exec_module
  File "<frozen importlib._bootstrap>", line 228, in _call_with_frames_removed
  File "C:\Users\sugan\AppData\Local\Red-DiscordBot\Red-DiscordBot\data\MyBot\cogs\CogManager\cogs\clsroom\__init__.py", line 1, in <module>
    from .clsroom import ClsRoom
  File "C:\Users\sugan\AppData\Local\Red-DiscordBot\Red-DiscordBot\data\MyBot\cogs\CogManager\cogs\clsroom\clsroom.py", line 11, in <module>
    import pandas as pd
ModuleNotFoundError: No module named 'pandas'
[2021-09-14 06:58:37] [ERROR] red: Package loading failed
Traceback (most recent call last):
  File "C:\Users\sugan\redenv\lib\site-packages\redbot\core\core_commands.py", line 176, in _load
    await bot.load_extension(spec)
  File "C:\Users\sugan\redenv\lib\site-packages\redbot\core\bot.py", line 1510, in load_extension
    lib = spec.loader.load_module()
  File "<frozen importlib._bootstrap_external>", line 529, in _check_name_wrapper
  File "<frozen importlib._bootstrap_external>", line 1029, in load_module
  File "<frozen importlib._bootstrap_external>", line 854, in load_module
  File "<frozen importlib._bootstrap>", line 274, in _load_module_shim
  File "<frozen importlib._bootstrap>", line 711, in _load
  File "<frozen importlib._bootstrap>", line 680, in _load_unlocked
  File "<frozen importlib._bootstrap_external>", line 850, in exec_module
  File "<frozen importlib._bootstrap>", line 228, in _call_with_frames_removed
  File "C:\Users\sugan\AppData\Local\Red-DiscordBot\Red-DiscordBot\data\MyBot\cogs\CogManager\cogs\groom\__init__.py", line 1, in <module>
    from .updts import Updts
  File "C:\Users\sugan\AppData\Local\Red-DiscordBot\Red-DiscordBot\data\MyBot\cogs\CogManager\cogs\groom\updts.py", line 10, in <module>
    from google.auth.transport.requests import Request
ModuleNotFoundError: No module named 'google.auth'
[2021-09-14 06:58:37] [ERROR] red: Package loading failed
Traceback (most recent call last):
  File "C:\Users\sugan\redenv\lib\site-packages\redbot\core\core_commands.py", line 176, in _load
    await bot.load_extension(spec)
  File "C:\Users\sugan\redenv\lib\site-packages\redbot\core\bot.py", line 1510, in load_extension
    lib = spec.loader.load_module()
  File "<frozen importlib._bootstrap_external>", line 529, in _check_name_wrapper
  File "<frozen importlib._bootstrap_external>", line 1029, in load_module
  File "<frozen importlib._bootstrap_external>", line 854, in load_module
  File "<frozen importlib._bootstrap>", line 274, in _load_module_shim
  File "<frozen importlib._bootstrap>", line 711, in _load
  File "<frozen importlib._bootstrap>", line 680, in _load_unlocked
  File "<frozen importlib._bootstrap_external>", line 850, in exec_module
  File "<frozen importlib._bootstrap>", line 228, in _call_with_frames_removed
  File "C:\Users\sugan\AppData\Local\Red-DiscordBot\Red-DiscordBot\data\MyBot\cogs\CogManager\cogs\rollnum\__init__.py", line 6, in <module>
    from .rollnum import rollnum
  File "C:\Users\sugan\AppData\Local\Red-DiscordBot\Red-DiscordBot\data\MyBot\cogs\CogManager\cogs\rollnum\rollnum.py", line 8, in <module>
    import pandas as pd
ModuleNotFoundError: No module named 'pandas'
[2021-09-14 06:59:30] [INFO] red.main: Shutting down with exit code: ExitCodes.SHUTDOWN
[2021-09-14 06:59:51] [INFO] red.main: Please wait, cleaning up a bit more
[2021-09-14 07:10:00] [INFO] red: Loading packages...
[2021-09-14 07:10:01] [INFO] red: Loaded packages: permissions, general, admin, alias, cleanup, customcom, downloader, filter, image, mod, modlog, google, speak, todo, typeracer
[2021-09-14 07:10:03] [INFO] red: Connected to Discord. Getting ready...
[2021-09-14 07:10:34] [ERROR] red: Package loading failed
Traceback (most recent call last):
  File "C:\Users\sugan\redenv\lib\site-packages\redbot\core\core_commands.py", line 176, in _load
    await bot.load_extension(spec)
  File "C:\Users\sugan\redenv\lib\site-packages\redbot\core\bot.py", line 1510, in load_extension
    lib = spec.loader.load_module()
  File "<frozen importlib._bootstrap_external>", line 529, in _check_name_wrapper
  File "<frozen importlib._bootstrap_external>", line 1029, in load_module
  File "<frozen importlib._bootstrap_external>", line 854, in load_module
  File "<frozen importlib._bootstrap>", line 274, in _load_module_shim
  File "<frozen importlib._bootstrap>", line 711, in _load
  File "<frozen importlib._bootstrap>", line 680, in _load_unlocked
  File "<frozen importlib._bootstrap_external>", line 850, in exec_module
  File "<frozen importlib._bootstrap>", line 228, in _call_with_frames_removed
  File "C:\Users\sugan\AppData\Local\Red-DiscordBot\Red-DiscordBot\data\MyBot\cogs\CogManager\cogs\clsroom\__init__.py", line 1, in <module>
    from .clsroom import ClsRoom
  File "C:\Users\sugan\AppData\Local\Red-DiscordBot\Red-DiscordBot\data\MyBot\cogs\CogManager\cogs\clsroom\clsroom.py", line 12, in <module>
    import requests
ModuleNotFoundError: No module named 'requests'
[2021-09-14 07:11:00] [INFO] red.main: Shutting down with exit code: ExitCodes.RESTART
[2021-09-14 07:11:00] [INFO] red.main: Please wait, cleaning up a bit more
[2021-09-14 07:11:51] [INFO] red: Loading packages...
[2021-09-14 07:11:52] [INFO] red: Loaded packages: permissions, general, admin, alias, cleanup, customcom, downloader, filter, image, mod, modlog, google, speak, todo, typeracer
[2021-09-14 07:11:54] [INFO] red: Connected to Discord. Getting ready...
[2021-09-14 07:12:46] [ERROR] red: Package loading failed
Traceback (most recent call last):
  File "C:\Users\sugan\redenv\lib\site-packages\redbot\core\core_commands.py", line 176, in _load
    await bot.load_extension(spec)
  File "C:\Users\sugan\redenv\lib\site-packages\redbot\core\bot.py", line 1510, in load_extension
    lib = spec.loader.load_module()
  File "<frozen importlib._bootstrap_external>", line 529, in _check_name_wrapper
  File "<frozen importlib._bootstrap_external>", line 1029, in load_module
  File "<frozen importlib._bootstrap_external>", line 854, in load_module
  File "<frozen importlib._bootstrap>", line 274, in _load_module_shim
  File "<frozen importlib._bootstrap>", line 711, in _load
  File "<frozen importlib._bootstrap>", line 680, in _load_unlocked
  File "<frozen importlib._bootstrap_external>", line 850, in exec_module
  File "<frozen importlib._bootstrap>", line 228, in _call_with_frames_removed
  File "C:\Users\sugan\AppData\Local\Red-DiscordBot\Red-DiscordBot\data\MyBot\cogs\CogManager\cogs\groom\__init__.py", line 1, in <module>
    from .updts import Updts
  File "C:\Users\sugan\AppData\Local\Red-DiscordBot\Red-DiscordBot\data\MyBot\cogs\CogManager\cogs\groom\updts.py", line 10, in <module>
    from google.auth.transport.requests import Request
ModuleNotFoundError: No module named 'google.auth'
[2021-09-14 07:12:46] [ERROR] red: Package loading failed
Traceback (most recent call last):
  File "C:\Users\sugan\redenv\lib\site-packages\redbot\core\core_commands.py", line 176, in _load
    await bot.load_extension(spec)
  File "C:\Users\sugan\redenv\lib\site-packages\redbot\core\bot.py", line 1510, in load_extension
    lib = spec.loader.load_module()
  File "<frozen importlib._bootstrap_external>", line 529, in _check_name_wrapper
  File "<frozen importlib._bootstrap_external>", line 1029, in load_module
  File "<frozen importlib._bootstrap_external>", line 854, in load_module
  File "<frozen importlib._bootstrap>", line 274, in _load_module_shim
  File "<frozen importlib._bootstrap>", line 711, in _load
  File "<frozen importlib._bootstrap>", line 680, in _load_unlocked
  File "<frozen importlib._bootstrap_external>", line 850, in exec_module
  File "<frozen importlib._bootstrap>", line 228, in _call_with_frames_removed
  File "C:\Users\sugan\AppData\Local\Red-DiscordBot\Red-DiscordBot\data\MyBot\cogs\CogManager\cogs\rollnum\__init__.py", line 6, in <module>
    from .rollnum import rollnum
  File "C:\Users\sugan\AppData\Local\Red-DiscordBot\Red-DiscordBot\data\MyBot\cogs\CogManager\cogs\rollnum\rollnum.py", line 9, in <module>
    from google.auth.transport.requests import Request
ModuleNotFoundError: No module named 'google.auth'
[2021-09-14 07:13:01] [ERROR] red: Package loading failed
Traceback (most recent call last):
  File "C:\Users\sugan\redenv\lib\site-packages\redbot\core\core_commands.py", line 176, in _load
    await bot.load_extension(spec)
  File "C:\Users\sugan\redenv\lib\site-packages\redbot\core\bot.py", line 1510, in load_extension
    lib = spec.loader.load_module()
  File "<frozen importlib._bootstrap_external>", line 529, in _check_name_wrapper
  File "<frozen importlib._bootstrap_external>", line 1029, in load_module
  File "<frozen importlib._bootstrap_external>", line 854, in load_module
  File "<frozen importlib._bootstrap>", line 274, in _load_module_shim
  File "<frozen importlib._bootstrap>", line 711, in _load
  File "<frozen importlib._bootstrap>", line 680, in _load_unlocked
  File "<frozen importlib._bootstrap_external>", line 850, in exec_module
  File "<frozen importlib._bootstrap>", line 228, in _call_with_frames_removed
  File "C:\Users\sugan\AppData\Local\Red-DiscordBot\Red-DiscordBot\data\MyBot\cogs\CogManager\cogs\groom\__init__.py", line 1, in <module>
    from .updts import Updts
  File "C:\Users\sugan\AppData\Local\Red-DiscordBot\Red-DiscordBot\data\MyBot\cogs\CogManager\cogs\groom\updts.py", line 10, in <module>
    from google.auth.transport.requests import Request
ModuleNotFoundError: No module named 'google.auth'
[2021-09-14 07:13:08] [ERROR] red: Package loading failed
Traceback (most recent call last):
  File "C:\Users\sugan\redenv\lib\site-packages\redbot\core\core_commands.py", line 176, in _load
    await bot.load_extension(spec)
  File "C:\Users\sugan\redenv\lib\site-packages\redbot\core\bot.py", line 1510, in load_extension
    lib = spec.loader.load_module()
  File "<frozen importlib._bootstrap_external>", line 529, in _check_name_wrapper
  File "<frozen importlib._bootstrap_external>", line 1029, in load_module
  File "<frozen importlib._bootstrap_external>", line 854, in load_module
  File "<frozen importlib._bootstrap>", line 274, in _load_module_shim
  File "<frozen importlib._bootstrap>", line 711, in _load
  File "<frozen importlib._bootstrap>", line 680, in _load_unlocked
  File "<frozen importlib._bootstrap_external>", line 850, in exec_module
  File "<frozen importlib._bootstrap>", line 228, in _call_with_frames_removed
  File "C:\Users\sugan\AppData\Local\Red-DiscordBot\Red-DiscordBot\data\MyBot\cogs\CogManager\cogs\rollnum\__init__.py", line 6, in <module>
    from .rollnum import rollnum
  File "C:\Users\sugan\AppData\Local\Red-DiscordBot\Red-DiscordBot\data\MyBot\cogs\CogManager\cogs\rollnum\rollnum.py", line 9, in <module>
    from google.auth.transport.requests import Request
ModuleNotFoundError: No module named 'google.auth'
[2021-09-14 07:13:16] [INFO] red.main: Shutting down with exit code: ExitCodes.RESTART
[2021-09-14 07:13:16] [INFO] red.main: Please wait, cleaning up a bit more
[2021-09-14 07:15:09] [INFO] red: Loading packages...
[2021-09-14 07:15:10] [INFO] red: Loaded packages: permissions, general, admin, alias, cleanup, customcom, downloader, filter, image, mod, modlog, google, speak, todo, typeracer, clsroom
[2021-09-14 07:15:13] [INFO] red: Connected to Discord. Getting ready...
[2021-09-14 07:15:26] [ERROR] red: Package loading failed
Traceback (most recent call last):
  File "C:\Users\sugan\redenv\lib\site-packages\redbot\core\core_commands.py", line 176, in _load
    await bot.load_extension(spec)
  File "C:\Users\sugan\redenv\lib\site-packages\redbot\core\bot.py", line 1510, in load_extension
    lib = spec.loader.load_module()
  File "<frozen importlib._bootstrap_external>", line 529, in _check_name_wrapper
  File "<frozen importlib._bootstrap_external>", line 1029, in load_module
  File "<frozen importlib._bootstrap_external>", line 854, in load_module
  File "<frozen importlib._bootstrap>", line 274, in _load_module_shim
  File "<frozen importlib._bootstrap>", line 711, in _load
  File "<frozen importlib._bootstrap>", line 680, in _load_unlocked
  File "<frozen importlib._bootstrap_external>", line 850, in exec_module
  File "<frozen importlib._bootstrap>", line 228, in _call_with_frames_removed
  File "C:\Users\sugan\AppData\Local\Red-DiscordBot\Red-DiscordBot\data\MyBot\cogs\CogManager\cogs\groom\__init__.py", line 1, in <module>
    from .updts import Updts
  File "C:\Users\sugan\AppData\Local\Red-DiscordBot\Red-DiscordBot\data\MyBot\cogs\CogManager\cogs\groom\updts.py", line 10, in <module>
    from google.auth.transport.requests import Request
ModuleNotFoundError: No module named 'google.auth'
[2021-09-14 07:18:05] [INFO] red.main: Shutting down with exit code: ExitCodes.SHUTDOWN
[2021-09-14 07:18:05] [INFO] red.main: Please wait, cleaning up a bit more
[2021-09-14 07:18:13] [INFO] red: Loading packages...
[2021-09-14 07:18:14] [INFO] red: Loaded packages: permissions, general, admin, alias, cleanup, customcom, downloader, filter, image, mod, modlog, google, speak, todo, typeracer, clsroom
[2021-09-14 07:18:16] [INFO] red: Connected to Discord. Getting ready...
[2021-09-14 07:18:23] [INFO] red.main: Shutting down with exit code: ExitCodes.RESTART
[2021-09-14 07:18:23] [INFO] red.main: Please wait, cleaning up a bit more
[2021-09-14 07:18:38] [INFO] red: Loading packages...
[2021-09-14 07:18:40] [INFO] red: Loaded packages: permissions, general, admin, alias, cleanup, customcom, downloader, filter, image, mod, modlog, google, speak, todo, typeracer, clsroom
[2021-09-14 07:18:42] [INFO] red: Connected to Discord. Getting ready...
[2021-09-14 07:18:46] [INFO] red.main: Shutting down with exit code: ExitCodes.SHUTDOWN
[2021-09-14 07:18:46] [INFO] red.main: Please wait, cleaning up a bit more
[2021-09-14 07:51:29] [INFO] red: Loading packages...
[2021-09-14 07:51:30] [INFO] red: Loaded packages: permissions, general, admin, alias, cleanup, customcom, downloader, filter, image, mod, modlog, google, speak, todo, typeracer, clsroom
[2021-09-14 07:51:33] [INFO] red: Connected to Discord. Getting ready...
[2021-09-14 08:32:52] [INFO] red.cleanup: Sugan(778438128527867915) deleted 2 messages sent by the bot in channel bot-commands.
[2021-09-14 08:50:10] [INFO] red.cleanup: Sugan(778438128527867915) deleted 2 messages sent by the bot in channel for-bot.
[2021-09-14 08:51:49] [INFO] red.cleanup: Sugan(778438128527867915) deleted 8 messages sent by the bot in channel for-bot.
[2021-09-14 08:51:52] [WARNING] discord.http: We are being rate limited. Retrying in 2.77 seconds. Handled under the bucket "853648824898813992:None:/channels/{channel_id}/messages/{message_id}"
[2021-09-14 09:14:12] [INFO] red.cleanup: Sugan(778438128527867915) deleted 10 messages sent by the bot in channel bot-commands.
[2021-09-14 09:14:55] [WARNING] discord.gateway: Shard ID 0 heartbeat blocked for more than 10 seconds.
Loop thread traceback (most recent call last):
  File "C:\Users\sugan\AppData\Local\Programs\Python\Python39\lib\runpy.py", line 197, in _run_module_as_main
    return _run_code(code, main_globals, None,
  File "C:\Users\sugan\AppData\Local\Programs\Python\Python39\lib\runpy.py", line 87, in _run_code
    exec(code, run_globals)
  File "C:\Users\sugan\redenv\Scripts\redbot.exe\__main__.py", line 7, in <module>
    sys.exit(main())
  File "C:\Users\sugan\redenv\lib\site-packages\redbot\__main__.py", line 526, in main
    loop.run_forever()
  File "C:\Users\sugan\AppData\Local\Programs\Python\Python39\lib\asyncio\windows_events.py", line 316, in run_forever
    super().run_forever()
  File "C:\Users\sugan\AppData\Local\Programs\Python\Python39\lib\asyncio\base_events.py", line 596, in run_forever
    self._run_once()
  File "C:\Users\sugan\AppData\Local\Programs\Python\Python39\lib\asyncio\base_events.py", line 1890, in _run_once
    handle._run()
  File "C:\Users\sugan\AppData\Local\Programs\Python\Python39\lib\asyncio\events.py", line 80, in _run
    self._context.run(self._callback, *self._args)
  File "C:\Users\sugan\redenv\lib\site-packages\discord\client.py", line 343, in _run_event
    await coro(*args, **kwargs)
  File "C:\Users\sugan\redenv\lib\site-packages\redbot\core\events.py", line 354, in on_message
    await bot.process_commands(message)
  File "C:\Users\sugan\redenv\lib\site-packages\redbot\core\bot.py", line 1479, in process_commands
    await self.invoke(ctx)
  File "C:\Users\sugan\redenv\lib\site-packages\discord\ext\commands\bot.py", line 939, in invoke
    await ctx.command.invoke(ctx)
  File "C:\Users\sugan\redenv\lib\site-packages\redbot\core\commands\commands.py", line 832, in invoke
    await super().invoke(ctx)
  File "C:\Users\sugan\redenv\lib\site-packages\discord\ext\commands\core.py", line 1348, in invoke
    await ctx.invoked_subcommand.invoke(ctx)
  File "C:\Users\sugan\redenv\lib\site-packages\discord\ext\commands\core.py", line 863, in invoke
    await injected(*ctx.args, **ctx.kwargs)
  File "C:\Users\sugan\redenv\lib\site-packages\discord\ext\commands\core.py", line 85, in wrapped
    ret = await coro(*args, **kwargs)
  File "C:\Users\sugan\redenv\lib\site-packages\redbot\cogs\cleanup\cleanup.py", line 667, in cleanup_self
    log.info(reason)
  File "C:\Users\sugan\AppData\Local\Programs\Python\Python39\lib\logging\__init__.py", line 1446, in info
    self._log(INFO, msg, args, **kwargs)
  File "C:\Users\sugan\AppData\Local\Programs\Python\Python39\lib\logging\__init__.py", line 1589, in _log
    self.handle(record)
  File "C:\Users\sugan\AppData\Local\Programs\Python\Python39\lib\logging\__init__.py", line 1599, in handle
    self.callHandlers(record)
  File "C:\Users\sugan\AppData\Local\Programs\Python\Python39\lib\logging\__init__.py", line 1661, in callHandlers
    hdlr.handle(record)
  File "C:\Users\sugan\AppData\Local\Programs\Python\Python39\lib\logging\__init__.py", line 952, in handle
    self.emit(record)
  File "C:\Users\sugan\redenv\lib\site-packages\redbot\logging.py", line 265, in emit
    self.console.print(
  File "C:\Users\sugan\redenv\lib\site-packages\rich\console.py", line 1615, in print
    self._buffer.extend(new_segments)
  File "C:\Users\sugan\redenv\lib\site-packages\rich\console.py", line 825, in __exit__
    self._exit_buffer()
  File "C:\Users\sugan\redenv\lib\site-packages\rich\console.py", line 784, in _exit_buffer
    self._check_buffer()
  File "C:\Users\sugan\redenv\lib\site-packages\rich\console.py", line 1864, in _check_buffer
    write(line)
  File "C:\Users\sugan\redenv\lib\site-packages\colorama\ansitowin32.py", line 41, in write
    self.__convertor.write(text)
  File "C:\Users\sugan\redenv\lib\site-packages\colorama\ansitowin32.py", line 162, in write
    self.write_and_convert(text)
  File "C:\Users\sugan\redenv\lib\site-packages\colorama\ansitowin32.py", line 187, in write_and_convert
    self.write_plain_text(text, cursor, start)
  File "C:\Users\sugan\redenv\lib\site-packages\colorama\ansitowin32.py", line 196, in write_plain_text
    self.wrapped.flush()

[2021-09-14 09:16:04] [WARNING] red.main: Please do not use Ctrl+C to Shutdown Red! (attempting to die gracefully...)
[2021-09-14 09:16:04] [ERROR] red.main: Received KeyboardInterrupt, treating as interrupt
[2021-09-14 09:16:04] [INFO] red.main: Signals.SIGINT received. Quitting...
[2021-09-14 09:16:04] [INFO] red.main: Please wait, cleaning up a bit more
[2021-09-14 09:16:20] [INFO] red: Loading packages...
[2021-09-14 09:16:21] [INFO] red: Loaded packages: permissions, general, admin, alias, cleanup, customcom, downloader, filter, image, mod, modlog, google, speak, todo, typeracer, clsroom
[2021-09-14 09:16:23] [INFO] red: Connected to Discord. Getting ready...
[2021-09-14 09:16:35] [INFO] red.cleanup: Sugan(778438128527867915) deleted 10 messages sent by the bot in channel bot-commands.
[2021-09-14 09:16:38] [WARNING] discord.http: We are being rate limited. Retrying in 2.48 seconds. Handled under the bucket "819856954095960105:None:/channels/{channel_id}/messages/{message_id}"
[2021-09-14 09:16:56] [INFO] red.cleanup: Sugan(778438128527867915) deleted 5 messages sent by the bot in channel bot-commands.
[2021-09-14 09:17:40] [INFO] red.main: Shutting down with exit code: ExitCodes.SHUTDOWN
[2021-09-14 09:17:40] [INFO] red.main: Please wait, cleaning up a bit more
[2021-09-14 09:18:26] [INFO] red: Loading packages...
[2021-09-14 09:18:27] [INFO] red: Loaded packages: permissions, general, admin, alias, cleanup, customcom, downloader, filter, image, mod, modlog, google, speak, todo, typeracer, clsroom
[2021-09-14 09:18:29] [INFO] red: Connected to Discord. Getting ready...
[2021-09-14 09:19:38] [INFO] red.cleanup: {dhiva}(497379893592719360) deleted 67 messages sent by the bot in channel bot-commands.
[2021-09-14 09:19:41] [WARNING] discord.http: We are being rate limited. Retrying in 2.06 seconds. Handled under the bucket "819856954095960105:None:/channels/{channel_id}/messages/{message_id}"
[2021-09-14 09:19:47] [WARNING] discord.http: We are being rate limited. Retrying in 2.50 seconds. Handled under the bucket "819856954095960105:None:/channels/{channel_id}/messages/{message_id}"
[2021-09-14 09:19:53] [WARNING] discord.http: We are being rate limited. Retrying in 1.95 seconds. Handled under the bucket "819856954095960105:None:/channels/{channel_id}/messages/{message_id}"
[2021-09-14 09:19:59] [WARNING] discord.http: We are being rate limited. Retrying in 1.59 seconds. Handled under the bucket "819856954095960105:None:/channels/{channel_id}/messages/{message_id}"
[2021-09-14 09:20:01] [INFO] red.cleanup: {dhiva}(497379893592719360) deleted 10 messages sent by the bot in Direct Message with {dhiva}#1852.
[2021-09-14 09:20:04] [WARNING] discord.http: We are being rate limited. Retrying in 2.20 seconds. Handled under the bucket "819856954095960105:None:/channels/{channel_id}/messages/{message_id}"
[2021-09-14 09:20:04] [WARNING] discord.http: We are being rate limited. Retrying in 0.87 seconds. Handled under the bucket "886951450637369344:None:/channels/{channel_id}/messages/{message_id}"
[2021-09-14 09:20:08] [WARNING] discord.http: We are being rate limited. Retrying in 2.33 seconds. Handled under the bucket "886951450637369344:None:/channels/{channel_id}/messages/{message_id}"
[2021-09-14 09:20:09] [WARNING] discord.http: We are being rate limited. Retrying in 2.42 seconds. Handled under the bucket "819856954095960105:None:/channels/{channel_id}/messages/{message_id}"
[2021-09-14 09:20:14] [WARNING] discord.http: We are being rate limited. Retrying in 2.68 seconds. Handled under the bucket "819856954095960105:None:/channels/{channel_id}/messages/{message_id}"
[2021-09-14 09:20:20] [WARNING] discord.http: We are being rate limited. Retrying in 2.67 seconds. Handled under the bucket "819856954095960105:None:/channels/{channel_id}/messages/{message_id}"
[2021-09-14 09:20:26] [WARNING] discord.http: We are being rate limited. Retrying in 2.69 seconds. Handled under the bucket "819856954095960105:None:/channels/{channel_id}/messages/{message_id}"
[2021-09-14 09:20:32] [WARNING] discord.http: We are being rate limited. Retrying in 2.24 seconds. Handled under the bucket "819856954095960105:None:/channels/{channel_id}/messages/{message_id}"
[2021-09-14 09:20:37] [WARNING] discord.http: We are being rate limited. Retrying in 2.53 seconds. Handled under the bucket "819856954095960105:None:/channels/{channel_id}/messages/{message_id}"
[2021-09-14 09:20:42] [WARNING] discord.http: We are being rate limited. Retrying in 2.66 seconds. Handled under the bucket "819856954095960105:None:/channels/{channel_id}/messages/{message_id}"
[2021-09-14 09:20:48] [WARNING] discord.http: We are being rate limited. Retrying in 2.62 seconds. Handled under the bucket "819856954095960105:None:/channels/{channel_id}/messages/{message_id}"
[2021-09-14 09:21:23] [INFO] red.cleanup: {dhiva}(497379893592719360) deleted 3 messages sent by the bot in Direct Message with {dhiva}#1852.
[2021-09-14 09:27:05] [INFO] red.cleanup: gooner_23(583963854304968734) deleted 3 messages sent by the bot in channel bot-commands.
[2021-09-14 09:27:54] [INFO] red.main: Shutting down with exit code: ExitCodes.SHUTDOWN
[2021-09-14 09:27:54] [INFO] red.main: Please wait, cleaning up a bit more
[2021-09-14 09:34:38] [INFO] red: Loading packages...
[2021-09-14 09:34:39] [INFO] red: Loaded packages: permissions, general, admin, alias, cleanup, customcom, downloader, filter, image, mod, modlog, google, speak, todo, typeracer, clsroom
[2021-09-14 09:34:41] [INFO] red: Connected to Discord. Getting ready...
[2021-09-14 09:36:01] [INFO] red.main: Shutting down with exit code: ExitCodes.SHUTDOWN
[2021-09-14 09:36:01] [INFO] red.main: Please wait, cleaning up a bit more
[2021-09-14 10:45:35] [INFO] red: Loading packages...
[2021-09-14 10:45:36] [INFO] red: Loaded packages: permissions, general, admin, alias, cleanup, customcom, downloader, filter, image, mod, modlog, google, speak, todo, typeracer, clsroom
[2021-09-14 10:45:38] [INFO] red: Connected to Discord. Getting ready...
[2021-09-14 10:47:51] [INFO] red.main: Shutting down with exit code: ExitCodes.SHUTDOWN
[2021-09-14 10:47:51] [INFO] red.main: Please wait, cleaning up a bit more
[2021-09-14 11:43:14] [INFO] red: Loading packages...
[2021-09-14 11:43:15] [INFO] red: Loaded packages: permissions, general, admin, alias, cleanup, customcom, downloader, filter, image, mod, modlog, google, speak, todo, typeracer, clsroom
[2021-09-14 11:43:17] [INFO] red: Connected to Discord. Getting ready...
[2021-09-14 11:49:54] [INFO] red.main: Shutting down with exit code: ExitCodes.SHUTDOWN
[2021-09-14 11:49:54] [INFO] red.main: Please wait, cleaning up a bit more
[2021-09-14 11:54:53] [INFO] red: Loading packages...
[2021-09-14 11:54:54] [INFO] red: Loaded packages: permissions, general, admin, alias, cleanup, customcom, downloader, filter, image, mod, modlog, google, speak, todo, typeracer, clsroom
[2021-09-14 11:54:57] [INFO] red: Connected to Discord. Getting ready...
[2021-09-14 15:37:01] [ERROR] discord.shard: Attempting a reconnect for shard ID 0 in 0.72s
Traceback (most recent call last):
  File "C:\Users\sugan\redenv\lib\site-packages\aiohttp\connector.py", line 999, in _create_direct_connection
    hosts = await asyncio.shield(host_resolved)
  File "C:\Users\sugan\redenv\lib\site-packages\aiohttp\connector.py", line 865, in _resolve_host
    addrs = await self._resolver.resolve(host, port, family=self._family)
  File "C:\Users\sugan\redenv\lib\site-packages\aiohttp\resolver.py", line 31, in resolve
    infos = await self._loop.getaddrinfo(
  File "C:\Users\sugan\AppData\Local\Programs\Python\Python39\lib\asyncio\base_events.py", line 856, in getaddrinfo
    return await self.run_in_executor(
  File "C:\Users\sugan\AppData\Local\Programs\Python\Python39\lib\concurrent\futures\thread.py", line 52, in run
    result = self.fn(*self.args, **self.kwargs)
  File "C:\Users\sugan\AppData\Local\Programs\Python\Python39\lib\socket.py", line 954, in getaddrinfo
    for res in _socket.getaddrinfo(host, port, family, type, proto, flags):
socket.gaierror: [Errno 11001] getaddrinfo failed

The above exception was the direct cause of the following exception:

Traceback (most recent call last):
  File "C:\Users\sugan\redenv\lib\site-packages\discord\shard.py", line 173, in reidentify
    self.ws = await asyncio.wait_for(coro, timeout=60.0)
  File "C:\Users\sugan\AppData\Local\Programs\Python\Python39\lib\asyncio\tasks.py", line 481, in wait_for
    return fut.result()
  File "C:\Users\sugan\redenv\lib\site-packages\discord\gateway.py", line 305, in from_client
    gateway = gateway or await client.http.get_gateway()
  File "C:\Users\sugan\redenv\lib\site-packages\discord\http.py", line 967, in get_gateway
    data = await self.request(Route('GET', '/gateway'))
  File "C:\Users\sugan\redenv\lib\site-packages\discord\http.py", line 192, in request
    async with self.__session.request(method, url, **kwargs) as r:
  File "C:\Users\sugan\redenv\lib\site-packages\aiohttp\client.py", line 1117, in __aenter__
    self._resp = await self._coro
  File "C:\Users\sugan\redenv\lib\site-packages\aiohttp\client.py", line 520, in _request
    conn = await self._connector.connect(
  File "C:\Users\sugan\redenv\lib\site-packages\aiohttp\connector.py", line 535, in connect
    proto = await self._create_connection(req, traces, timeout)
  File "C:\Users\sugan\redenv\lib\site-packages\aiohttp\connector.py", line 892, in _create_connection
    _, proto = await self._create_direct_connection(req, traces, timeout)
  File "C:\Users\sugan\redenv\lib\site-packages\aiohttp\connector.py", line 1011, in _create_direct_connection
    raise ClientConnectorError(req.connection_key, exc) from exc
aiohttp.client_exceptions.ClientConnectorError: Cannot connect to host discord.com:443 ssl:default [getaddrinfo failed]
[2021-09-14 15:37:03] [ERROR] discord.shard: Attempting a reconnect for shard ID 0 in 2.12s
Traceback (most recent call last):
  File "C:\Users\sugan\redenv\lib\site-packages\aiohttp\connector.py", line 999, in _create_direct_connection
    hosts = await asyncio.shield(host_resolved)
  File "C:\Users\sugan\redenv\lib\site-packages\aiohttp\connector.py", line 865, in _resolve_host
    addrs = await self._resolver.resolve(host, port, family=self._family)
  File "C:\Users\sugan\redenv\lib\site-packages\aiohttp\resolver.py", line 31, in resolve
    infos = await self._loop.getaddrinfo(
  File "C:\Users\sugan\AppData\Local\Programs\Python\Python39\lib\asyncio\base_events.py", line 856, in getaddrinfo
    return await self.run_in_executor(
  File "C:\Users\sugan\AppData\Local\Programs\Python\Python39\lib\concurrent\futures\thread.py", line 52, in run
    result = self.fn(*self.args, **self.kwargs)
  File "C:\Users\sugan\AppData\Local\Programs\Python\Python39\lib\socket.py", line 954, in getaddrinfo
    for res in _socket.getaddrinfo(host, port, family, type, proto, flags):
socket.gaierror: [Errno 11001] getaddrinfo failed

The above exception was the direct cause of the following exception:

Traceback (most recent call last):
  File "C:\Users\sugan\redenv\lib\site-packages\discord\shard.py", line 187, in reconnect
    self.ws = await asyncio.wait_for(coro, timeout=60.0)
  File "C:\Users\sugan\AppData\Local\Programs\Python\Python39\lib\asyncio\tasks.py", line 481, in wait_for
    return fut.result()
  File "C:\Users\sugan\redenv\lib\site-packages\discord\gateway.py", line 305, in from_client
    gateway = gateway or await client.http.get_gateway()
  File "C:\Users\sugan\redenv\lib\site-packages\discord\http.py", line 967, in get_gateway
    data = await self.request(Route('GET', '/gateway'))
  File "C:\Users\sugan\redenv\lib\site-packages\discord\http.py", line 192, in request
    async with self.__session.request(method, url, **kwargs) as r:
  File "C:\Users\sugan\redenv\lib\site-packages\aiohttp\client.py", line 1117, in __aenter__
    self._resp = await self._coro
  File "C:\Users\sugan\redenv\lib\site-packages\aiohttp\client.py", line 520, in _request
    conn = await self._connector.connect(
  File "C:\Users\sugan\redenv\lib\site-packages\aiohttp\connector.py", line 535, in connect
    proto = await self._create_connection(req, traces, timeout)
  File "C:\Users\sugan\redenv\lib\site-packages\aiohttp\connector.py", line 892, in _create_connection
    _, proto = await self._create_direct_connection(req, traces, timeout)
  File "C:\Users\sugan\redenv\lib\site-packages\aiohttp\connector.py", line 1011, in _create_direct_connection
    raise ClientConnectorError(req.connection_key, exc) from exc
aiohttp.client_exceptions.ClientConnectorError: Cannot connect to host discord.com:443 ssl:default [getaddrinfo failed]
[2021-09-14 15:37:06] [ERROR] discord.shard: Attempting a reconnect for shard ID 0 in 4.10s
Traceback (most recent call last):
  File "C:\Users\sugan\redenv\lib\site-packages\aiohttp\connector.py", line 999, in _create_direct_connection
    hosts = await asyncio.shield(host_resolved)
  File "C:\Users\sugan\redenv\lib\site-packages\aiohttp\connector.py", line 865, in _resolve_host
    addrs = await self._resolver.resolve(host, port, family=self._family)
  File "C:\Users\sugan\redenv\lib\site-packages\aiohttp\resolver.py", line 31, in resolve
    infos = await self._loop.getaddrinfo(
  File "C:\Users\sugan\AppData\Local\Programs\Python\Python39\lib\asyncio\base_events.py", line 856, in getaddrinfo
    return await self.run_in_executor(
  File "C:\Users\sugan\AppData\Local\Programs\Python\Python39\lib\concurrent\futures\thread.py", line 52, in run
    result = self.fn(*self.args, **self.kwargs)
  File "C:\Users\sugan\AppData\Local\Programs\Python\Python39\lib\socket.py", line 954, in getaddrinfo
    for res in _socket.getaddrinfo(host, port, family, type, proto, flags):
socket.gaierror: [Errno 11001] getaddrinfo failed

The above exception was the direct cause of the following exception:

Traceback (most recent call last):
  File "C:\Users\sugan\redenv\lib\site-packages\discord\shard.py", line 187, in reconnect
    self.ws = await asyncio.wait_for(coro, timeout=60.0)
  File "C:\Users\sugan\AppData\Local\Programs\Python\Python39\lib\asyncio\tasks.py", line 481, in wait_for
    return fut.result()
  File "C:\Users\sugan\redenv\lib\site-packages\discord\gateway.py", line 305, in from_client
    gateway = gateway or await client.http.get_gateway()
  File "C:\Users\sugan\redenv\lib\site-packages\discord\http.py", line 967, in get_gateway
    data = await self.request(Route('GET', '/gateway'))
  File "C:\Users\sugan\redenv\lib\site-packages\discord\http.py", line 192, in request
    async with self.__session.request(method, url, **kwargs) as r:
  File "C:\Users\sugan\redenv\lib\site-packages\aiohttp\client.py", line 1117, in __aenter__
    self._resp = await self._coro
  File "C:\Users\sugan\redenv\lib\site-packages\aiohttp\client.py", line 520, in _request
    conn = await self._connector.connect(
  File "C:\Users\sugan\redenv\lib\site-packages\aiohttp\connector.py", line 535, in connect
    proto = await self._create_connection(req, traces, timeout)
  File "C:\Users\sugan\redenv\lib\site-packages\aiohttp\connector.py", line 892, in _create_connection
    _, proto = await self._create_direct_connection(req, traces, timeout)
  File "C:\Users\sugan\redenv\lib\site-packages\aiohttp\connector.py", line 1011, in _create_direct_connection
    raise ClientConnectorError(req.connection_key, exc) from exc
aiohttp.client_exceptions.ClientConnectorError: Cannot connect to host discord.com:443 ssl:default [getaddrinfo failed]
[2021-09-14 15:37:11] [ERROR] discord.shard: Attempting a reconnect for shard ID 0 in 10.65s
Traceback (most recent call last):
  File "C:\Users\sugan\redenv\lib\site-packages\aiohttp\connector.py", line 999, in _create_direct_connection
    hosts = await asyncio.shield(host_resolved)
  File "C:\Users\sugan\redenv\lib\site-packages\aiohttp\connector.py", line 865, in _resolve_host
    addrs = await self._resolver.resolve(host, port, family=self._family)
  File "C:\Users\sugan\redenv\lib\site-packages\aiohttp\resolver.py", line 31, in resolve
    infos = await self._loop.getaddrinfo(
  File "C:\Users\sugan\AppData\Local\Programs\Python\Python39\lib\asyncio\base_events.py", line 856, in getaddrinfo
    return await self.run_in_executor(
  File "C:\Users\sugan\AppData\Local\Programs\Python\Python39\lib\concurrent\futures\thread.py", line 52, in run
    result = self.fn(*self.args, **self.kwargs)
  File "C:\Users\sugan\AppData\Local\Programs\Python\Python39\lib\socket.py", line 954, in getaddrinfo
    for res in _socket.getaddrinfo(host, port, family, type, proto, flags):
socket.gaierror: [Errno 11001] getaddrinfo failed

The above exception was the direct cause of the following exception:

Traceback (most recent call last):
  File "C:\Users\sugan\redenv\lib\site-packages\discord\shard.py", line 187, in reconnect
    self.ws = await asyncio.wait_for(coro, timeout=60.0)
  File "C:\Users\sugan\AppData\Local\Programs\Python\Python39\lib\asyncio\tasks.py", line 481, in wait_for
    return fut.result()
  File "C:\Users\sugan\redenv\lib\site-packages\discord\gateway.py", line 305, in from_client
    gateway = gateway or await client.http.get_gateway()
  File "C:\Users\sugan\redenv\lib\site-packages\discord\http.py", line 967, in get_gateway
    data = await self.request(Route('GET', '/gateway'))
  File "C:\Users\sugan\redenv\lib\site-packages\discord\http.py", line 192, in request
    async with self.__session.request(method, url, **kwargs) as r:
  File "C:\Users\sugan\redenv\lib\site-packages\aiohttp\client.py", line 1117, in __aenter__
    self._resp = await self._coro
  File "C:\Users\sugan\redenv\lib\site-packages\aiohttp\client.py", line 520, in _request
    conn = await self._connector.connect(
  File "C:\Users\sugan\redenv\lib\site-packages\aiohttp\connector.py", line 535, in connect
    proto = await self._create_connection(req, traces, timeout)
  File "C:\Users\sugan\redenv\lib\site-packages\aiohttp\connector.py", line 892, in _create_connection
    _, proto = await self._create_direct_connection(req, traces, timeout)
  File "C:\Users\sugan\redenv\lib\site-packages\aiohttp\connector.py", line 1011, in _create_direct_connection
    raise ClientConnectorError(req.connection_key, exc) from exc
aiohttp.client_exceptions.ClientConnectorError: Cannot connect to host discord.com:443 ssl:default [getaddrinfo failed]
[2021-09-14 15:37:22] [ERROR] discord.shard: Attempting a reconnect for shard ID 0 in 26.58s
Traceback (most recent call last):
  File "C:\Users\sugan\redenv\lib\site-packages\aiohttp\connector.py", line 999, in _create_direct_connection
    hosts = await asyncio.shield(host_resolved)
  File "C:\Users\sugan\redenv\lib\site-packages\aiohttp\connector.py", line 865, in _resolve_host
    addrs = await self._resolver.resolve(host, port, family=self._family)
  File "C:\Users\sugan\redenv\lib\site-packages\aiohttp\resolver.py", line 31, in resolve
    infos = await self._loop.getaddrinfo(
  File "C:\Users\sugan\AppData\Local\Programs\Python\Python39\lib\asyncio\base_events.py", line 856, in getaddrinfo
    return await self.run_in_executor(
  File "C:\Users\sugan\AppData\Local\Programs\Python\Python39\lib\concurrent\futures\thread.py", line 52, in run
    result = self.fn(*self.args, **self.kwargs)
  File "C:\Users\sugan\AppData\Local\Programs\Python\Python39\lib\socket.py", line 954, in getaddrinfo
    for res in _socket.getaddrinfo(host, port, family, type, proto, flags):
socket.gaierror: [Errno 11001] getaddrinfo failed

The above exception was the direct cause of the following exception:

Traceback (most recent call last):
  File "C:\Users\sugan\redenv\lib\site-packages\discord\shard.py", line 187, in reconnect
    self.ws = await asyncio.wait_for(coro, timeout=60.0)
  File "C:\Users\sugan\AppData\Local\Programs\Python\Python39\lib\asyncio\tasks.py", line 481, in wait_for
    return fut.result()
  File "C:\Users\sugan\redenv\lib\site-packages\discord\gateway.py", line 305, in from_client
    gateway = gateway or await client.http.get_gateway()
  File "C:\Users\sugan\redenv\lib\site-packages\discord\http.py", line 967, in get_gateway
    data = await self.request(Route('GET', '/gateway'))
  File "C:\Users\sugan\redenv\lib\site-packages\discord\http.py", line 192, in request
    async with self.__session.request(method, url, **kwargs) as r:
  File "C:\Users\sugan\redenv\lib\site-packages\aiohttp\client.py", line 1117, in __aenter__
    self._resp = await self._coro
  File "C:\Users\sugan\redenv\lib\site-packages\aiohttp\client.py", line 520, in _request
    conn = await self._connector.connect(
  File "C:\Users\sugan\redenv\lib\site-packages\aiohttp\connector.py", line 535, in connect
    proto = await self._create_connection(req, traces, timeout)
  File "C:\Users\sugan\redenv\lib\site-packages\aiohttp\connector.py", line 892, in _create_connection
    _, proto = await self._create_direct_connection(req, traces, timeout)
  File "C:\Users\sugan\redenv\lib\site-packages\aiohttp\connector.py", line 1011, in _create_direct_connection
    raise ClientConnectorError(req.connection_key, exc) from exc
aiohttp.client_exceptions.ClientConnectorError: Cannot connect to host discord.com:443 ssl:default [getaddrinfo failed]
[2021-09-14 15:37:49] [ERROR] discord.shard: Attempting a reconnect for shard ID 0 in 40.97s
Traceback (most recent call last):
  File "C:\Users\sugan\redenv\lib\site-packages\aiohttp\connector.py", line 999, in _create_direct_connection
    hosts = await asyncio.shield(host_resolved)
  File "C:\Users\sugan\redenv\lib\site-packages\aiohttp\connector.py", line 865, in _resolve_host
    addrs = await self._resolver.resolve(host, port, family=self._family)
  File "C:\Users\sugan\redenv\lib\site-packages\aiohttp\resolver.py", line 31, in resolve
    infos = await self._loop.getaddrinfo(
  File "C:\Users\sugan\AppData\Local\Programs\Python\Python39\lib\asyncio\base_events.py", line 856, in getaddrinfo
    return await self.run_in_executor(
  File "C:\Users\sugan\AppData\Local\Programs\Python\Python39\lib\concurrent\futures\thread.py", line 52, in run
    result = self.fn(*self.args, **self.kwargs)
  File "C:\Users\sugan\AppData\Local\Programs\Python\Python39\lib\socket.py", line 954, in getaddrinfo
    for res in _socket.getaddrinfo(host, port, family, type, proto, flags):
socket.gaierror: [Errno 11001] getaddrinfo failed

The above exception was the direct cause of the following exception:

Traceback (most recent call last):
  File "C:\Users\sugan\redenv\lib\site-packages\discord\shard.py", line 187, in reconnect
    self.ws = await asyncio.wait_for(coro, timeout=60.0)
  File "C:\Users\sugan\AppData\Local\Programs\Python\Python39\lib\asyncio\tasks.py", line 481, in wait_for
    return fut.result()
  File "C:\Users\sugan\redenv\lib\site-packages\discord\gateway.py", line 305, in from_client
    gateway = gateway or await client.http.get_gateway()
  File "C:\Users\sugan\redenv\lib\site-packages\discord\http.py", line 967, in get_gateway
    data = await self.request(Route('GET', '/gateway'))
  File "C:\Users\sugan\redenv\lib\site-packages\discord\http.py", line 192, in request
    async with self.__session.request(method, url, **kwargs) as r:
  File "C:\Users\sugan\redenv\lib\site-packages\aiohttp\client.py", line 1117, in __aenter__
    self._resp = await self._coro
  File "C:\Users\sugan\redenv\lib\site-packages\aiohttp\client.py", line 520, in _request
    conn = await self._connector.connect(
  File "C:\Users\sugan\redenv\lib\site-packages\aiohttp\connector.py", line 535, in connect
    proto = await self._create_connection(req, traces, timeout)
  File "C:\Users\sugan\redenv\lib\site-packages\aiohttp\connector.py", line 892, in _create_connection
    _, proto = await self._create_direct_connection(req, traces, timeout)
  File "C:\Users\sugan\redenv\lib\site-packages\aiohttp\connector.py", line 1011, in _create_direct_connection
    raise ClientConnectorError(req.connection_key, exc) from exc
aiohttp.client_exceptions.ClientConnectorError: Cannot connect to host discord.com:443 ssl:default [getaddrinfo failed]
[2021-09-14 16:49:24] [INFO] red.main: Shutting down with exit code: ExitCodes.SHUTDOWN
[2021-09-14 16:49:24] [INFO] red.main: Please wait, cleaning up a bit more
[2021-09-14 18:20:12] [INFO] red: Loading packages...
[2021-09-14 18:20:17] [INFO] red: Loaded packages: permissions, general, admin, alias, cleanup, customcom, downloader, filter, image, mod, modlog, google, speak, todo, typeracer, clsroom
[2021-09-14 18:20:19] [INFO] red: Connected to Discord. Getting ready...
[2021-09-14 18:49:22] [INFO] red.main: Shutting down with exit code: ExitCodes.RESTART
[2021-09-14 18:49:22] [INFO] red.main: Please wait, cleaning up a bit more
[2021-09-14 18:50:08] [INFO] red: Loading packages...
[2021-09-14 18:50:09] [INFO] red: Loaded packages: permissions, general, admin, alias, cleanup, customcom, downloader, filter, image, mod, modlog, google, speak, todo, typeracer, clsroom
[2021-09-14 18:50:12] [INFO] red: Connected to Discord. Getting ready...
[2021-09-14 18:50:46] [INFO] red.main: Shutting down with exit code: ExitCodes.RESTART
[2021-09-14 18:50:46] [INFO] red.main: Please wait, cleaning up a bit more
[2021-09-14 18:50:52] [INFO] red: Loading packages...
[2021-09-14 18:50:53] [INFO] red: Loaded packages: permissions, general, admin, alias, cleanup, customcom, downloader, filter, image, mod, modlog, google, speak, todo, typeracer, clsroom
[2021-09-14 18:50:56] [INFO] red: Connected to Discord. Getting ready...
[2021-09-14 19:02:20] [CRITICAL] red.main: The main bot task didn't handle an exception and has crashed
Traceback (most recent call last):
  File "C:\Users\sugan\redenv\lib\site-packages\redbot\__main__.py", line 475, in red_exception_handler
    red_task.result()
  File "C:\Users\sugan\redenv\lib\site-packages\redbot\__main__.py", line 387, in run_bot
    await red.start(token, bot=True, cli_flags=cli_flags)
  File "C:\Users\sugan\redenv\lib\site-packages\redbot\core\bot.py", line 1202, in start
    return await super().start(*args, **kwargs)
  File "C:\Users\sugan\redenv\lib\site-packages\discord\client.py", line 666, in start
    await self.connect(reconnect=reconnect)
  File "C:\Users\sugan\redenv\lib\site-packages\discord\shard.py", line 435, in connect
    raise item.error
  File "C:\Users\sugan\redenv\lib\site-packages\discord\shard.py", line 151, in worker
    await self.ws.poll_event()
  File "C:\Users\sugan\redenv\lib\site-packages\discord\gateway.py", line 582, in poll_event
    raise ConnectionClosed(self.socket, shard_id=self.shard_id, code=code) from None
discord.errors.ConnectionClosed: Shard ID 0 WebSocket closed with 4004
[2021-09-14 19:02:21] [WARNING] red.main: Attempting to die as gracefully as possible...
[2021-09-14 19:02:21] [INFO] red.main: Shutting down from unhandled exception
[2021-09-14 19:09:38] [WARNING] red.main: Please do not use Ctrl+C to Shutdown Red! (attempting to die gracefully...)
[2021-09-14 19:09:38] [ERROR] red.main: Received KeyboardInterrupt, treating as interrupt
[2021-09-14 19:09:38] [INFO] red.main: Signals.SIGINT received. Quitting...
[2021-09-14 19:09:38] [INFO] red.main: Please wait, cleaning up a bit more
[2021-09-14 19:09:43] [INFO] red: Loading packages...
[2021-09-14 19:09:44] [INFO] red: Loaded packages: permissions, general, admin, alias, cleanup, customcom, downloader, filter, image, mod, modlog, google, speak, todo, typeracer, clsroom
[2021-09-14 19:09:44] [CRITICAL] red.main: This token doesn't seem to be valid.
[2021-09-14 19:09:48] [INFO] red.main: Shutting down with exit code: 1
[2021-09-14 19:09:48] [INFO] red.main: Please wait, cleaning up a bit more
